<sdf version='1.4'>
  <world name='default'>
    <light name='sun' type='directional'>
      <cast_shadows>1</cast_shadows>
      <pose>0 0 10 0 -0 0</pose>
      <diffuse>0.8 0.8 0.8 1</diffuse>
      <specular>0.2 0.2 0.2 1</specular>
      <attenuation>
        <range>1000</range>
        <constant>0.9</constant>
        <linear>0.01</linear>
        <quadratic>0.001</quadratic>
      </attenuation>
      <direction>-0.5 0.1 -0.9</direction>
    </light>
    <model name='ground_plane'>
      <static>1</static>
      <link name='link'>
        <collision name='collision'>
          <geometry>
            <plane>
              <normal>0 0 1</normal>
              <size>100 100</size>
            </plane>
          </geometry>
          <surface>
            <friction>
              <ode>
                <mu>100</mu>
                <mu2>50</mu2>
              </ode>
            </friction>
            <bounce/>
            <contact>
              <ode/>
            </contact>
          </surface>
          <max_contacts>10</max_contacts>
        </collision>
        <visual name='visual'>
          <cast_shadows>0</cast_shadows>
          <geometry>
            <plane>
              <normal>0 0 1</normal>
              <size>100 100</size>
            </plane>
          </geometry>
          <material>
            <script>
              <uri>file://media/materials/scripts/gazebo.material</uri>
              <name>Gazebo/Grey</name>
            </script>
          </material>
        </visual>
        <velocity_decay>
          <linear>0</linear>
          <angular>0</angular>
        </velocity_decay>
        <self_collide>0</self_collide>
        <kinematic>0</kinematic>
        <gravity>1</gravity>
      </link>
    </model>
    <physics type='ode'>
      <max_step_size>0.001</max_step_size>
      <real_time_factor>1</real_time_factor>
      <real_time_update_rate>1000</real_time_update_rate>
      <gravity>0 0 -9.8</gravity>
    </physics>
    <scene>
      <ambient>0.4 0.4 0.4 1</ambient>
      <background>0.7 0.7 0.7 1</background>
      <shadows>1</shadows>
    </scene>
    <spherical_coordinates>
      <surface_model>EARTH_WGS84</surface_model>
      <latitude_deg>0</latitude_deg>
      <longitude_deg>0</longitude_deg>
      <elevation>0</elevation>
      <heading_deg>0</heading_deg>
    </spherical_coordinates>
    <model name='world'>
      <link name='wall_1'>
        <pose>0 0 0 0 -0 0</pose>
        <inertial>
          <pose>-0.468535 8.12398e-05 -0.0281215 0 -0 0</pose>
          <mass>80.01</mass>
          <inertia>
            <ixx>62.5105</ixx>
            <ixy>-0.0111705</ixy>
            <ixz>-0.258296</ixz>
            <iyy>202.433</iyy>
            <iyz>-0.00018279</iyz>
            <izz>256.731</izz>
          </inertia>
        </inertial>
        <collision name='wall_1_collision'>
          <pose>0 1.2 0 0 -0 0</pose>
          <geometry>
            <box>
              <size>4 0.1 0.3</size>
            </box>
          </geometry>
          <surface>
            <contact>
              <ode/>
            </contact>
            <friction>
              <ode/>
            </friction>
            <bounce/>
          </surface>
          <max_contacts>10</max_contacts>
        </collision>
        <collision name='wall_1_collision_orange_box'>
          <pose>1.25 0.65 0 0 -0 0</pose>
          <geometry>
            <box>
              <size>0.31496 0.31496 0.29778</size>
            </box>
          </geometry>
          <surface>
            <contact>
              <ode/>
            </contact>
            <friction>
              <ode/>
            </friction>
            <bounce/>
          </surface>
          <surface>
            <contact>
              <ode/>
            </contact>
            <friction>
              <ode/>
            </friction>
          </surface>
          <max_contacts>10</max_contacts>
        </collision>
        <collision name='wall_1_collision_wall_10'>
          <pose>1.75 0 -0.075 0 -0 0</pose>
          <geometry>
            <box>
              <size>0.5 2.4 0.15</size>
            </box>
          </geometry>
          <surface>
            <contact>
              <ode/>
            </contact>
            <friction>
              <ode/>
            </friction>
            <bounce/>
          </surface>
          <surface>
            <contact>
              <ode/>
            </contact>
            <friction>
              <ode/>
            </friction>
          </surface>
          <max_contacts>10</max_contacts>
        </collision>
        <collision name='wall_1_collision_wall_2'>
          <pose>2 0 0 0 -0 0</pose>
          <geometry>
            <box>
              <size>0.1 -2.4 0.3</size>
            </box>
          </geometry>
          <surface>
            <contact>
              <ode/>
            </contact>
            <friction>
              <ode/>
            </friction>
            <bounce/>
          </surface>
          <surface>
            <contact>
              <ode/>
            </contact>
            <friction>
              <ode/>
            </friction>
          </surface>
          <max_contacts>10</max_contacts>
        </collision>
        <collision name='wall_1_collision_wall_3'>
          <pose>0 -1.2 0 0 -0 0</pose>
          <geometry>
            <box>
              <size>4 0.1 0.3</size>
            </box>
          </geometry>
          <surface>
            <contact>
              <ode/>
            </contact>
            <friction>
              <ode/>
            </friction>
            <bounce/>
          </surface>
          <surface>
            <contact>
              <ode/>
            </contact>
            <friction>
              <ode/>
            </friction>
          </surface>
          <max_contacts>10</max_contacts>
        </collision>
        <collision name='wall_1_collision_wall_6'>
          <pose>-2 -0.8 0 0 -0 0</pose>
          <geometry>
            <box>
              <size>0.1 0.8 0.3</size>
            </box>
          </geometry>
          <surface>
            <contact>
              <ode/>
            </contact>
            <friction>
              <ode/>
            </friction>
            <bounce/>
          </surface>
          <surface>
            <contact>
              <ode/>
            </contact>
            <friction>
              <ode/>
            </friction>
          </surface>
          <max_contacts>10</max_contacts>
        </collision>
        <collision name='wall_1_collision_wall_7'>
          <pose>-2 0.8 0 0 -0 0</pose>
          <geometry>
            <box>
              <size>0.1 0.8 0.3</size>
            </box>
          </geometry>
          <surface>
            <contact>
              <ode/>
            </contact>
            <friction>
              <ode/>
            </friction>
            <bounce/>
          </surface>
          <surface>
            <contact>
              <ode/>
            </contact>
            <friction>
              <ode/>
            </friction>
          </surface>
          <max_contacts>10</max_contacts>
        </collision>
        <collision name='wall_1_collision_wall_8'>
          <pose>-1.75 0.8 -0.075 0 -0 0</pose>
          <geometry>
            <box>
              <size>0.5 0.8 0.15</size>
            </box>
          </geometry>
          <surface>
            <contact>
              <ode/>
            </contact>
            <friction>
              <ode/>
            </friction>
            <bounce/>
          </surface>
          <surface>
            <contact>
              <ode/>
            </contact>
            <friction>
              <ode/>
            </friction>
          </surface>
          <max_contacts>10</max_contacts>
        </collision>
        <collision name='wall_1_collision_wall_9'>
          <pose>-1.75 -0.8 -0.075 0 -0 0</pose>
          <geometry>
            <box>
              <size>0.5 0.8 0.15</size>
            </box>
          </geometry>
          <surface>
            <contact>
              <ode/>
            </contact>
            <friction>
              <ode/>
            </friction>
            <bounce/>
          </surface>
          <surface>
            <contact>
              <ode/>
            </contact>
            <friction>
              <ode/>
            </friction>
          </surface>
          <max_contacts>10</max_contacts>
        </collision>
        <visual name='wall_1_visual'>
          <pose>0 1.2 0 0 -0 0</pose>
          <geometry>
            <box>
              <size>4 0.1 0.3</size>
            </box>
          </geometry>
          <material>
            <script>
              <name>Gazebo/Gray</name>
              <uri>__default__</uri>
            </script>
          </material>
        </visual>
        <visual name='wall_1_visual_orange_box'>
          <pose>1.25 0.65 0 0 -0 0</pose>
          <geometry>
            <box>
              <size>0.31496 0.31496 0.29778</size>
            </box>
          </geometry>
          <material>
            <script>
              <name>Gazebo/Orange</name>
              <uri>__default__</uri>
            </script>
          </material>
        </visual>
        <visual name='wall_1_visual_wall_10'>
          <pose>1.75 0 -0.075 0 -0 0</pose>
          <geometry>
            <box>
              <size>0.5 2.4 0.15</size>
            </box>
          </geometry>
          <material>
            <script>
              <name>Gazebo/Gray</name>
              <uri>__default__</uri>
            </script>
          </material>
          <material>
            <script>
              <name>Gazebo/Gray</name>
              <uri>__default__</uri>
            </script>
          </material>
        </visual>
        <visual name='wall_1_visual_wall_2'>
          <pose>2 0 0 0 -0 0</pose>
          <geometry>
            <box>
              <size>0.1 -2.4 0.3</size>
            </box>
          </geometry>
          <material>
            <script>
              <name>Gazebo/Gray</name>
              <uri>__default__</uri>
            </script>
          </material>
        </visual>
        <visual name='wall_1_visual_wall_3'>
          <pose>0 -1.2 0 0 -0 0</pose>
          <geometry>
            <box>
              <size>4 0.1 0.3</size>
            </box>
          </geometry>
          <material>
            <script>
              <name>Gazebo/Gray</name>
              <uri>__default__</uri>
            </script>
          </material>
        </visual>
        <visual name='wall_1_visual_wall_6'>
          <pose>-2 -0.8 0 0 -0 0</pose>
          <geometry>
            <box>
              <size>0.1 0.8 0.3</size>
            </box>
          </geometry>
          <material>
            <script>
              <name>Gazebo/Gray</name>
              <uri>__default__</uri>
            </script>
          </material>
        </visual>
        <visual name='wall_1_visual_wall_7'>
          <pose>-2 0.8 0 0 -0 0</pose>
          <geometry>
            <box>
              <size>0.1 0.8 0.3</size>
            </box>
          </geometry>
          <material>
            <script>
              <name>Gazebo/Gray</name>
              <uri>__default__</uri>
            </script>
          </material>
        </visual>
        <visual name='wall_1_visual_wall_8'>
          <pose>-1.75 0.8 -0.075 0 -0 0</pose>
          <geometry>
            <box>
              <size>0.5 0.8 0.15</size>
            </box>
          </geometry>
          <material>
            <script>
              <name>Gazebo/Gray</name>
              <uri>__default__</uri>
            </script>
          </material>
        </visual>
        <visual name='wall_1_visual_wall_9'>
          <pose>-1.75 -0.8 -0.075 0 -0 0</pose>
          <geometry>
            <box>
              <size>0.5 0.8 0.15</size>
            </box>
          </geometry>
          <material>
            <script>
              <name>Gazebo/Gray</name>
              <uri>__default__</uri>
            </script>
          </material>
        </visual>
        <velocity_decay>
          <linear>0</linear>
          <angular>0</angular>
        </velocity_decay>
        <velocity_decay>
          <linear>0</linear>
          <angular>0</angular>
        </velocity_decay>
        <velocity_decay>
          <linear>0</linear>
          <angular>0</angular>
        </velocity_decay>
        <velocity_decay>
          <linear>0</linear>
          <angular>0</angular>
        </velocity_decay>
        <velocity_decay>
          <linear>0</linear>
          <angular>0</angular>
        </velocity_decay>
        <velocity_decay>
          <linear>0</linear>
          <angular>0</angular>
        </velocity_decay>
        <velocity_decay>
          <linear>0</linear>
          <angular>0</angular>
        </velocity_decay>
        <velocity_decay>
          <linear>0</linear>
          <angular>0</angular>
        </velocity_decay>
        <gravity>1</gravity>
        <velocity_decay>
          <linear>0</linear>
          <angular>0</angular>
        </velocity_decay>
        <self_collide>1</self_collide>
        <kinematic>0</kinematic>
      </link>
      <pose>0 0 0.2 0 -0 0</pose>
      <static>0</static>
    </model>
    <model name='youbot'>
      <link name='base_footprint'>
        <pose>0 0 0 0 -0 0</pose>
        <inertial>
          <pose>-3.79454 -0.000601311 0.00952866 0 -0 0</pose>
          <mass>24.405</mass>
          <inertia>
            <ixx>6.88983</ixx>
            <ixy>-0.00367752</ixy>
            <ixz>1.23348</ixz>
            <iyy>7.01292</iyy>
            <iyz>0.000953705</iyz>
            <izz>4.94144</izz>
          </inertia>
        </inertial>
        <collision name='base_footprint_collision'>
          <pose>-3.8 0 -0.05 0 -0 0</pose>
          <geometry>
            <box>
              <size>0.001 0.001 0.001</size>
            </box>
          </geometry>
          <max_contacts>10</max_contacts>
          <surface>
            <bounce/>
            <friction>
              <ode/>
            </friction>
            <contact>
              <ode/>
            </contact>
          </surface>
        </collision>
        <collision name='base_footprint_collision_arm_link_0'>
          <pose>-3.657 0 0.046 0 -0 0</pose>
          <geometry>
            <mesh>
              <scale>1 1 1</scale>
              <uri>/home/lex/catkin_ws/src/youbot/youbot_description/meshes/youbot_arm/arm0_convex.dae</uri>
            </mesh>
          </geometry>
          <surface>
            <contact>
              <ode/>
            </contact>
            <friction>
              <ode/>
            </friction>
            <bounce/>
          </surface>
          <max_contacts>10</max_contacts>
        </collision>
        <collision name='base_footprint_collision_base_laser_front_link'>
          <pose>-3.5 0 -0.03 0 -0 0</pose>
          <geometry>
            <mesh>
              <scale>1 1 1</scale>
              <uri>/home/lex/catkin_ws/src/youbot/youbot_description/meshes/sensors/hokuyo_convex.dae</uri>
            </mesh>
          </geometry>
          <surface>
            <contact>
              <ode/>
            </contact>
            <friction>
              <ode/>
            </friction>
            <bounce/>
          </surface>
          <max_contacts>10</max_contacts>
        </collision>
        <collision name='base_footprint_collision_base_link'>
          <pose>-3.8 0 0 0 -0 0</pose>
          <geometry>
            <mesh>
              <scale>1 1 1</scale>
              <uri>/home/lex/catkin_ws/src/youbot/youbot_description/meshes/youbot_base/base_convex.dae</uri>
            </mesh>
          </geometry>
          <max_contacts>10</max_contacts>
          <surface>
            <bounce/>
            <friction>
              <ode/>
            </friction>
            <contact>
              <ode/>
            </contact>
          </surface>
        </collision>
        <collision name='base_footprint_collision_kinect_camera_rgb_kinect2_ir_link'>
          <pose>-3.38279 -0.0475 0.577385 0 0.314159 0</pose>
          <geometry>
            <sphere>
              <radius>0.0005</radius>
            </sphere>
          </geometry>
          <surface>
            <contact>
              <ode/>
            </contact>
            <friction>
              <ode/>
            </friction>
            <bounce/>
          </surface>
          <max_contacts>10</max_contacts>
        </collision>
        <collision name='base_footprint_collision_kinect_camera_rgb_kinect2_link'>
          <pose>-3.4 0 0.42 0 0.314159 0</pose>
          <geometry>
            <sphere>
              <radius>0.0005</radius>
            </sphere>
          </geometry>
          <max_contacts>10</max_contacts>
          <surface>
            <bounce/>
            <friction>
              <ode/>
            </friction>
            <contact>
              <ode/>
            </contact>
          </surface>
        </collision>
        <collision name='base_footprint_collision_kinect_camera_rgb_kinect2_rgb_link'>
          <pose>-3.38279 -0.09925 0.577385 0 0.314159 0</pose>
          <geometry>
            <sphere>
              <radius>0.0005</radius>
            </sphere>
          </geometry>
          <surface>
            <contact>
              <ode/>
            </contact>
            <friction>
              <ode/>
            </friction>
            <bounce/>
          </surface>
          <max_contacts>10</max_contacts>
        </collision>
        <collision name='base_footprint_collision_plate_link'>
          <pose>-3.959 0 0.046 0 -0 0</pose>
          <geometry>
            <mesh>
              <scale>1 1 1</scale>
              <uri>/home/lex/catkin_ws/src/youbot/youbot_description/meshes/youbot_plate/plate_convex.dae</uri>
            </mesh>
          </geometry>
          <max_contacts>10</max_contacts>
          <surface>
            <bounce/>
            <friction>
              <ode/>
            </friction>
            <contact>
              <ode/>
            </contact>
          </surface>
        </collision>
        <visual name='base_footprint_visual'>
          <pose>-3.8 0 0 0 -0 0</pose>
          <geometry>
            <box>
              <size>0.001 0.001 0.001</size>
            </box>
          </geometry>
        </visual>
        <visual name='base_footprint_visual_arm_link_0'>
          <pose>-3.657 0 0.046 0 -0 0</pose>
          <geometry>
            <mesh>
              <scale>1 1 1</scale>
              <uri>/home/lex/catkin_ws/src/youbot/youbot_description/meshes/youbot_arm/arm0.dae</uri>
            </mesh>
          </geometry>
          <material>
            <script>
              <name>youbot/DarkGrey</name>
              <uri>__default__</uri>
            </script>
          </material>
        </visual>
        <visual name='base_footprint_visual_base_laser_front_link'>
          <pose>-3.5 0 -0.03 0 -0 0</pose>
          <geometry>
            <mesh>
              <scale>1 1 1</scale>
              <uri>/home/lex/catkin_ws/src/youbot/youbot_description/meshes/sensors/hokuyo.dae</uri>
            </mesh>
          </geometry>
        </visual>
        <visual name='base_footprint_visual_base_link'>
          <pose>-3.8 0 0 0 -0 0</pose>
          <geometry>
            <mesh>
              <scale>1 1 1</scale>
              <uri>/home/lex/catkin_ws/src/youbot/youbot_description/meshes/youbot_base/base.dae</uri>
            </mesh>
          </geometry>
        </visual>
        <visual name='base_footprint_visual_kinect_camera_rgb_kinect2_ir_link'>
          <pose>-3.38279 -0.0475 0.577385 0 0.314159 0</pose>
          <geometry>
            <sphere>
              <radius>0.0005</radius>
            </sphere>
          </geometry>
          <material>
            <script>
              <name>Gazebo/Black</name>
              <uri>__default__</uri>
            </script>
          </material>
        </visual>
        <visual name='base_footprint_visual_kinect_camera_rgb_kinect2_link'>
          <pose>-3.49701 -0.148 0.45152 0 0.314159 0</pose>
          <geometry>
            <mesh>
              <scale>0.001 0.001 0.001</scale>
              <uri>/home/lex/catkin_ws/src/youbot/common-sensors/common_sensors/meshes/sensors/kinect2_assembly.STL</uri>
            </mesh>
          </geometry>
        </visual>
        <visual name='base_footprint_visual_kinect_camera_rgb_kinect2_rgb_link'>
          <pose>-3.38279 -0.09925 0.577385 -1.88496 1.51296e-12 -1.5708</pose>
          <geometry>
            <sphere>
              <radius>0.0005</radius>
            </sphere>
          </geometry>
          <material>
            <script>
              <name>Gazebo/Black</name>
              <uri>__default__</uri>
            </script>
          </material>
        </visual>
        <visual name='base_footprint_visual_plate_link'>
          <pose>-3.959 0 0.046 0 -0 0</pose>
          <geometry>
            <mesh>
              <scale>1 1 1</scale>
              <uri>/home/lex/catkin_ws/src/youbot/youbot_description/meshes/youbot_plate/plate.dae</uri>
            </mesh>
          </geometry>
        </visual>
        <velocity_decay>
          <linear>0</linear>
          <angular>0</angular>
        </velocity_decay>
        <velocity_decay>
          <linear>0</linear>
          <angular>0</angular>
        </velocity_decay>
        <sensor name='base_laser_front' type='ray'>
          <always_on>1</always_on>
          <update_rate>10</update_rate>
          <visualize>0</visualize>
          <ray>
            <scan>
              <horizontal>
                <samples>150</samples>
                <resolution>1</resolution>
                <min_angle>-1.57</min_angle>
                <max_angle>1.57</max_angle>
              </horizontal>
            </scan>
            <range>
              <min>0.05</min>
              <max>5.6</max>
              <resolution>0.36</resolution>
            </range>
          </ray>
          <plugin name='gazebo_ros_base_laser_front_controller' filename='libgazebo_ros_laser.so'>
            <gaussianNoise>0.005</gaussianNoise>
            <alwaysOn>true</alwaysOn>
            <updateRate>10</updateRate>
            <topicName>scan</topicName>
            <frameName>/base_laser_front_link</frameName>
            <robotNamespace>/</robotNamespace>
          </plugin>
          <pose>-3.5 0 -0.03 0 -0 0</pose>
        </sensor>
        <velocity_decay>
          <linear>0</linear>
          <angular>0</angular>
        </velocity_decay>
        <sensor name='kinect_camera_rgb_ir_sensor' type='depth'>
          <always_on>1</always_on>
          <update_rate>1</update_rate>
          <camera name='__default__'>
            <horizontal_fov>0.994838</horizontal_fov>
            <image>
              <format>L8</format>
              <width>640</width>
              <height>480</height>
            </image>
            <clip>
              <near>0.01</near>
              <far>5</far>
            </clip>
          </camera>
          <plugin name='kinect_camera_rgb_kinect2_ir_link_controller' filename='libgazebo_ros_openni_kinect.so'>
            <baseline>0.2</baseline>
            <alwaysOn>true</alwaysOn>
            <updateRate>1.0</updateRate>
            <cameraName>head_mount_kinect2_ir</cameraName>
            <imageTopicName>/head_mount_kinect2/ir/image_raw</imageTopicName>
            <cameraInfoTopicName>/head_mount_kinect2/ir/camera_info</cameraInfoTopicName>
            <depthImageTopicName>/head_mount_kinect2/depth/image_raw</depthImageTopicName>
            <depthImageCameraInfoTopicName>/head_mount_kinect2/depth/camera_info</depthImageCameraInfoTopicName>
            <pointCloudTopicName>/head_mount_kinect2/depth/points</pointCloudTopicName>
            <frameName>kinect_camera_rgb_kinect2_ir_optical_frame</frameName>
            <pointCloudCutoff>0.5</pointCloudCutoff>
            <distortionK1>0.00000001</distortionK1>
            <distortionK2>0.00000001</distortionK2>
            <distortionK3>0.00000001</distortionK3>
            <distortionT1>0.00000001</distortionT1>
            <distortionT2>0.00000001</distortionT2>
            <CxPrime>0</CxPrime>
            <Cx>0</Cx>
            <Cy>0</Cy>
            <focalLength>0</focalLength>
            <hackBaseline>0</hackBaseline>
            <robotNamespace>/</robotNamespace>
          </plugin>
          <pose>-3.38279 -0.0475 0.577385 0 0.314159 0</pose>
        </sensor>
        <gravity>1</gravity>
        <velocity_decay>
          <linear>0</linear>
          <angular>0</angular>
        </velocity_decay>
        <self_collide>0</self_collide>
        <sensor name='kinect_camera_rgb_rgb_sensor' type='depth'>
          <always_on>1</always_on>
          <update_rate>1</update_rate>
          <camera name='__default__'>
            <horizontal_fov>0.994838</horizontal_fov>
            <image>
              <format>B8G8R8</format>
              <width>640</width>
              <height>480</height>
            </image>
            <clip>
              <near>0.01</near>
              <far>5</far>
            </clip>
          </camera>
          <plugin name='kinect_camera_rgb_kinect2_rgb_link_controller' filename='libgazebo_ros_openni_kinect.so'>
            <alwaysOn>true</alwaysOn>
            <updateRate>1.0</updateRate>
            <cameraName>head_mount_kinect2_rgb</cameraName>
            <imageTopicName>/head_mount_kinect2/rgb/image_raw</imageTopicName>
            <cameraInfoTopicName>/head_mount_kinect2/rgb/camera_info</cameraInfoTopicName>
            <depthImageTopicName>/head_mount_kinect2/depth/image_raw</depthImageTopicName>
            <depthImageCameraInfoTopicName>/head_mount_kinect2/depth/camera_info</depthImageCameraInfoTopicName>
            <pointCloudTopicName>/head_mount_kinect2/depth_registered/points</pointCloudTopicName>
            <frameName>kinect_camera_rgb_kinect2_rgb_optical_frame</frameName>
            <pointCloudCutoff>0.5</pointCloudCutoff>
            <distortionK1>0.00000001</distortionK1>
            <distortionK2>0.00000001</distortionK2>
            <distortionK3>0.00000001</distortionK3>
            <distortionT1>0.00000001</distortionT1>
            <distortionT2>0.00000001</distortionT2>
            <CxPrime>0</CxPrime>
            <Cx>0</Cx>
            <Cy>0</Cy>
            <focalLength>0</focalLength>
            <hackBaseline>0</hackBaseline>
            <robotNamespace>/</robotNamespace>
          </plugin>
          <pose>-3.38279 -0.09925 0.577385 0 0.314159 0</pose>
        </sensor>
        <kinematic>0</kinematic>
      </link>
      <link name='arm_link_1'>
        <pose>-3.633 0 0.142 0 -0 2.96706</pose>
        <inertial>
          <pose>0.01489 0.00213 0.00213 0 -0 0</pose>
          <mass>2.412</mass>
          <inertia>
            <ixx>0.003863</ixx>
            <ixy>-0.000979</ixy>
            <ixz>0</ixz>
            <iyy>0.006196</iyy>
            <iyz>0</iyz>
            <izz>0.006369</izz>
          </inertia>
        </inertial>
        <collision name='arm_link_1_collision'>
          <pose>0 0 0 0 -0 0</pose>
          <geometry>
            <mesh>
              <scale>1 1 1</scale>
              <uri>/home/lex/catkin_ws/src/youbot/youbot_description/meshes/youbot_arm/arm1_convex.dae</uri>
            </mesh>
          </geometry>
          <surface>
            <contact>
              <ode/>
            </contact>
            <friction>
              <ode/>
            </friction>
            <bounce/>
          </surface>
          <max_contacts>10</max_contacts>
        </collision>
        <visual name='arm_link_1_visual'>
          <pose>0 0 0 0 -0 0</pose>
          <geometry>
            <mesh>
              <scale>1 1 1</scale>
              <uri>/home/lex/catkin_ws/src/youbot/youbot_description/meshes/youbot_arm/arm1.dae</uri>
            </mesh>
          </geometry>
        </visual>
        <gravity>1</gravity>
        <velocity_decay>
          <linear>0</linear>
          <angular>0</angular>
        </velocity_decay>
        <self_collide>0</self_collide>
        <kinematic>0</kinematic>
      </link>
      <joint name='arm_joint_1' type='revolute'>
        <child>arm_link_1</child>
        <parent>base_footprint</parent>
        <axis>
          <xyz>0 0 -1</xyz>
          <limit>
            <lower>0</lower>
            <upper>5.89921</upper>
            <effort>9.5</effort>
            <velocity>1.5708</velocity>
          </limit>
          <dynamics>
            <damping>1</damping>
          </dynamics>
        </axis>
      </joint>
      <link name='arm_link_2'>
        <pose>-3.6655 0.00573039 0.161 1.31349e-16 -1.13446 2.96706</pose>
        <inertial>
          <pose>0.10453 0.0017 -0.00297 0 -0 0</pose>
          <mass>1.155</mass>
          <inertia>
            <ixx>0.000823</ixx>
            <ixy>0</ixy>
            <ixz>-0</ixz>
            <iyy>0.004447</iyy>
            <iyz>0</iyz>
            <izz>0.004439</izz>
          </inertia>
        </inertial>
        <collision name='arm_link_2_collision'>
          <pose>0 -0.032 0.078 0 -0 0</pose>
          <geometry>
            <mesh>
              <scale>1 1 1</scale>
              <uri>/home/lex/catkin_ws/src/youbot/youbot_description/meshes/youbot_arm/arm2_convex.dae</uri>
            </mesh>
          </geometry>
          <surface>
            <contact>
              <ode/>
            </contact>
            <friction>
              <ode/>
            </friction>
            <bounce/>
          </surface>
          <max_contacts>10</max_contacts>
        </collision>
        <visual name='arm_link_2_visual'>
          <pose>0 -0.032 0.078 0 -0 0</pose>
          <geometry>
            <mesh>
              <scale>1 1 1</scale>
              <uri>/home/lex/catkin_ws/src/youbot/youbot_description/meshes/youbot_arm/arm2.dae</uri>
            </mesh>
          </geometry>
        </visual>
        <gravity>1</gravity>
        <velocity_decay>
          <linear>0</linear>
          <angular>0</angular>
        </velocity_decay>
        <self_collide>0</self_collide>
        <kinematic>0</kinematic>
      </link>
      <joint name='arm_joint_2' type='revolute'>
        <child>arm_link_2</child>
        <parent>arm_link_1</parent>
        <axis>
          <xyz>-0.173648 -0.984808 0</xyz>
          <limit>
            <lower>0</lower>
            <upper>2.70526</upper>
            <effort>9.5</effort>
            <velocity>1.5708</velocity>
          </limit>
          <dynamics>
            <damping>1</damping>
          </dynamics>
        </axis>
      </joint>
      <link name='arm_link_3'>
        <pose>-3.52716 -0.0186633 0.226506 -2.66145e-16 1.41372 2.96706</pose>
        <inertial>
          <pose>0.0001 0.0967 0.02107 0 -0 0</pose>
          <mass>0.934</mass>
          <inertia>
            <ixx>0.002459</ixx>
            <ixy>0</ixy>
            <ixz>0</ixz>
            <iyy>0.002571</iyy>
            <iyz>-0</iyz>
            <izz>0.000535</izz>
          </inertia>
        </inertial>
        <collision name='arm_link_3_collision'>
          <pose>0 0.028 0.079 0 -0 0</pose>
          <geometry>
            <mesh>
              <scale>1 1 1</scale>
              <uri>/home/lex/catkin_ws/src/youbot/youbot_description/meshes/youbot_arm/arm3_convex.dae</uri>
            </mesh>
          </geometry>
          <surface>
            <contact>
              <ode/>
            </contact>
            <friction>
              <ode/>
            </friction>
            <bounce/>
          </surface>
          <max_contacts>10</max_contacts>
        </collision>
        <visual name='arm_link_3_visual'>
          <pose>0 0.028 0.079 0 -0 0</pose>
          <geometry>
            <mesh>
              <scale>1 1 1</scale>
              <uri>/home/lex/catkin_ws/src/youbot/youbot_description/meshes/youbot_arm/arm3.dae</uri>
            </mesh>
          </geometry>
        </visual>
        <gravity>1</gravity>
        <velocity_decay>
          <linear>0</linear>
          <angular>0</angular>
        </velocity_decay>
        <self_collide>0</self_collide>
        <kinematic>0</kinematic>
      </link>
      <joint name='arm_joint_3' type='revolute'>
        <child>arm_link_3</child>
        <parent>arm_link_2</parent>
        <axis>
          <xyz>-0.173648 -0.984808 0</xyz>
          <limit>
            <lower>-5.18363</lower>
            <upper>0</upper>
            <effort>6</effort>
            <velocity>1.5708</velocity>
          </limit>
          <dynamics>
            <damping>1</damping>
          </dynamics>
        </axis>
      </joint>
      <link name='arm_link_4'>
        <pose>-3.65847 0.00449058 0.247624 0 -0.375246 2.96706</pose>
        <inertial>
          <pose>0.00011 0.05103 -0.02319 0 -0 0</pose>
          <mass>0.877</mass>
          <inertia>
            <ixx>0.000869</ixx>
            <ixy>0</ixy>
            <ixz>-0</ixz>
            <iyy>0.001173</iyy>
            <iyz>-0.000231</iyz>
            <izz>0.001091</izz>
          </inertia>
        </inertial>
        <collision name='arm_link_4_collision'>
          <pose>0 -0.01 0.029 0 -0 0</pose>
          <geometry>
            <mesh>
              <scale>1 1 1</scale>
              <uri>/home/lex/catkin_ws/src/youbot/youbot_description/meshes/youbot_arm/arm4_convex.dae</uri>
            </mesh>
          </geometry>
          <surface>
            <contact>
              <ode/>
            </contact>
            <friction>
              <ode/>
            </friction>
            <bounce/>
          </surface>
          <max_contacts>10</max_contacts>
        </collision>
        <visual name='arm_link_4_visual'>
          <pose>0 -0.01 0.029 0 -0 0</pose>
          <geometry>
            <mesh>
              <scale>1 1 1</scale>
              <uri>/home/lex/catkin_ws/src/youbot/youbot_description/meshes/youbot_arm/arm4.dae</uri>
            </mesh>
          </geometry>
        </visual>
        <gravity>1</gravity>
        <velocity_decay>
          <linear>0</linear>
          <angular>0</angular>
        </velocity_decay>
        <self_collide>0</self_collide>
        <kinematic>0</kinematic>
      </link>
      <joint name='arm_joint_4' type='revolute'>
        <child>arm_link_4</child>
        <parent>arm_link_3</parent>
        <axis>
          <xyz>-0.173648 -0.984808 0</xyz>
          <limit>
            <lower>0</lower>
            <upper>3.57792</upper>
            <effort>2</effort>
            <velocity>1.5708</velocity>
          </limit>
          <dynamics>
            <damping>1</damping>
          </dynamics>
        </axis>
      </joint>
      <link name='arm_link_5'>
        <pose>-3.60971 -0.00410605 0.367846 -0.0850522 0.365926 -0.408446</pose>
        <inertial>
          <pose>0 0.000822365 -0.0120351 0 -0 0</pose>
          <mass>0.351</mass>
          <inertia>
            <ixx>0.0103003</ixx>
            <ixy>0</ixy>
            <ixz>0</ixz>
            <iyy>0.0103593</iyy>
            <iyz>1.38404e-06</iyz>
            <izz>0.0101191</izz>
          </inertia>
        </inertial>
        <collision name='arm_link_5_collision'>
          <pose>0.003 0 -0.034 0 -0 0</pose>
          <geometry>
            <mesh>
              <scale>1 1 1</scale>
              <uri>/home/lex/catkin_ws/src/youbot/youbot_description/meshes/youbot_arm/arm5_convex.dae</uri>
            </mesh>
          </geometry>
          <surface>
            <contact>
              <ode/>
            </contact>
            <friction>
              <ode/>
            </friction>
            <bounce/>
          </surface>
          <max_contacts>10</max_contacts>
        </collision>
        <collision name='arm_link_5_collision_gripper_palm_link'>
          <pose>0 0 0 0 -0 0</pose>
          <geometry>
            <mesh>
              <scale>1 1 1</scale>
              <uri>/home/lex/catkin_ws/src/youbot/youbot_description/meshes/youbot_gripper/palm_convex.dae</uri>
            </mesh>
          </geometry>
          <surface>
            <contact>
              <ode/>
            </contact>
            <friction>
              <ode/>
            </friction>
            <bounce/>
          </surface>
          <surface>
            <contact>
              <ode/>
            </contact>
            <friction>
              <ode/>
            </friction>
          </surface>
          <max_contacts>10</max_contacts>
        </collision>
        <visual name='arm_link_5_visual'>
          <pose>0.003 0 -0.034 0 -0 0</pose>
          <geometry>
            <mesh>
              <scale>1 1 1</scale>
              <uri>/home/lex/catkin_ws/src/youbot/youbot_description/meshes/youbot_arm/arm5.dae</uri>
            </mesh>
          </geometry>
        </visual>
        <visual name='arm_link_5_visual_gripper_palm_link'>
          <pose>0 0 0 0 -0 0</pose>
          <geometry>
            <mesh>
              <scale>1 1 1</scale>
              <uri>/home/lex/catkin_ws/src/youbot/youbot_description/meshes/youbot_gripper/palm.dae</uri>
            </mesh>
          </geometry>
          <material>
            <script>
              <name>Gazebo/Black</name>
              <uri>__default__</uri>
            </script>
          </material>
        </visual>
        <velocity_decay>
          <linear>0</linear>
          <angular>0</angular>
        </velocity_decay>
        <gravity>1</gravity>
        <velocity_decay>
          <linear>0</linear>
          <angular>0</angular>
        </velocity_decay>
        <self_collide>1</self_collide>
        <kinematic>0</kinematic>
      </link>
      <joint name='arm_joint_5' type='revolute'>
        <child>arm_link_5</child>
        <parent>arm_link_4</parent>
        <axis>
          <xyz>-0.360933 0.063642 -0.930418</xyz>
          <limit>
            <lower>0</lower>
            <upper>5.84685</upper>
            <effort>1</effort>
            <velocity>1.5708</velocity>
          </limit>
          <dynamics>
            <damping>1</damping>
          </dynamics>
        </axis>
      </joint>
      <link name='gripper_finger_link_l'>
        <pose>-3.58674 -0.00110518 0.408579 0.0850522 -0.365926 2.73315</pose>
        <inertial>
          <pose>0 -0.001 0 0 -0 0</pose>
          <mass>0.01</mass>
          <inertia>
            <ixx>0.01</ixx>
            <ixy>0</ixy>
            <ixz>0</ixz>
            <iyy>0.01</iyy>
            <iyz>0</iyz>
            <izz>0.01</izz>
          </inertia>
        </inertial>
        <collision name='gripper_finger_link_l_collision'>
          <pose>0 0 0 0 -0 0</pose>
          <geometry>
            <mesh>
              <scale>1 1 1</scale>
              <uri>/home/lex/catkin_ws/src/youbot/youbot_description/meshes/youbot_gripper/finger_convex.dae</uri>
            </mesh>
          </geometry>
          <max_contacts>10</max_contacts>
          <surface>
            <bounce/>
            <friction>
              <ode/>
            </friction>
            <contact>
              <ode/>
            </contact>
          </surface>
        </collision>
        <visual name='gripper_finger_link_l_visual'>
          <pose>0 0 0 0 -0 0</pose>
          <geometry>
            <mesh>
              <scale>1 1 1</scale>
              <uri>/home/lex/catkin_ws/src/youbot/youbot_description/meshes/youbot_gripper/finger.dae</uri>
            </mesh>
          </geometry>
        </visual>
        <velocity_decay>
          <linear>0</linear>
          <angular>0</angular>
        </velocity_decay>
        <self_collide>0</self_collide>
        <kinematic>0</kinematic>
        <gravity>1</gravity>
      </link>
      <joint name='gripper_finger_joint_l' type='prismatic'>
        <child>gripper_finger_link_l</child>
        <parent>arm_link_5</parent>
        <axis>
          <xyz>0.367852 0.926495 -0.0793254</xyz>
          <limit>
            <lower>0</lower>
            <upper>0.0115</upper>
            <effort>1</effort>
            <velocity>0.1</velocity>
          </limit>
          <dynamics>
            <damping>1</damping>
          </dynamics>
        </axis>
      </joint>
      <link name='gripper_finger_link_r'>
        <pose>-3.59263 -0.0159291 0.409848 -0.0850522 0.365926 -0.408446</pose>
        <inertial>
          <pose>0 -0.001 0 0 -0 0</pose>
          <mass>0.01</mass>
          <inertia>
            <ixx>0.01</ixx>
            <ixy>0</ixy>
            <ixz>0</ixz>
            <iyy>0.01</iyy>
            <iyz>0</iyz>
            <izz>0.01</izz>
          </inertia>
        </inertial>
        <collision name='gripper_finger_link_r_collision'>
          <pose>0 0 0 0 -0 0</pose>
          <geometry>
            <mesh>
              <scale>1 1 1</scale>
              <uri>/home/lex/catkin_ws/src/youbot/youbot_description/meshes/youbot_gripper/finger_convex.dae</uri>
            </mesh>
          </geometry>
          <max_contacts>10</max_contacts>
          <surface>
            <bounce/>
            <friction>
              <ode/>
            </friction>
            <contact>
              <ode/>
            </contact>
          </surface>
        </collision>
        <visual name='gripper_finger_link_r_visual'>
          <pose>0 0 0 0 -0 0</pose>
          <geometry>
            <mesh>
              <scale>1 1 1</scale>
              <uri>/home/lex/catkin_ws/src/youbot/youbot_description/meshes/youbot_gripper/finger.dae</uri>
            </mesh>
          </geometry>
        </visual>
        <velocity_decay>
          <linear>0</linear>
          <angular>0</angular>
        </velocity_decay>
        <self_collide>0</self_collide>
        <kinematic>0</kinematic>
        <gravity>1</gravity>
      </link>
      <joint name='gripper_finger_joint_r' type='prismatic'>
        <child>gripper_finger_link_r</child>
        <parent>arm_link_5</parent>
        <axis>
          <xyz>-0.367852 -0.926495 0.0793254</xyz>
          <limit>
            <lower>0</lower>
            <upper>0.0115</upper>
            <effort>1</effort>
            <velocity>0.1</velocity>
          </limit>
          <dynamics>
            <damping>1</damping>
          </dynamics>
        </axis>
      </joint>
      <link name='caster_link_bl'>
        <pose>-4.028 0.158 -0.034 0 -0 0</pose>
        <inertial>
          <pose>0 0 0 0 -0 0</pose>
          <mass>0.1</mass>
          <inertia>
            <ixx>0.0124118</ixx>
            <ixy>-0.000711734</ixy>
            <ixz>0.00050273</ixz>
            <iyy>0.0152182</iyy>
            <iyz>-4.27347e-06</iyz>
            <izz>0.011764</izz>
          </inertia>
        </inertial>
        <gravity>1</gravity>
        <velocity_decay>
          <linear>0</linear>
          <angular>0</angular>
        </velocity_decay>
        <self_collide>0</self_collide>
        <kinematic>0</kinematic>
      </link>
      <joint name='caster_joint_bl' type='revolute'>
        <child>caster_link_bl</child>
        <parent>base_footprint</parent>
        <axis>
          <xyz>0 0 1</xyz>
          <limit>
            <lower>-1e+16</lower>
            <upper>1e+16</upper>
          </limit>
          <dynamics>
            <damping>1</damping>
          </dynamics>
        </axis>
      </joint>
      <link name='wheel_link_bl'>
        <pose>-4.028 0.158 -0.034 0 -0 0</pose>
        <inertial>
          <pose>0 0 0 0 -0 0</pose>
          <mass>0.4</mass>
          <inertia>
            <ixx>0.0124118</ixx>
            <ixy>-0.000711734</ixy>
            <ixz>0.00050273</ixz>
            <iyy>0.0152182</iyy>
            <iyz>-4.27347e-06</iyz>
            <izz>0.011764</izz>
          </inertia>
        </inertial>
        <collision name='wheel_link_bl_collision'>
          <pose>0 0 0 1.5708 -0 0</pose>
          <geometry>
            <cylinder>
              <length>0.05</length>
              <radius>0.05</radius>
            </cylinder>
          </geometry>
          <surface>
            <contact>
              <ode>
                <kp>1e+06</kp>
                <kd>100</kd>
              </ode>
            </contact>
            <friction>
              <ode/>
            </friction>
            <bounce/>
          </surface>
          <max_contacts>10</max_contacts>
        </collision>
        <visual name='wheel_link_bl_visual'>
          <pose>0 0 0 0 -0 0</pose>
          <geometry>
            <sphere>
              <radius>0.05</radius>
            </sphere>
          </geometry>
          <material>
            <script>
              <name>youbot/Orange</name>
              <uri>__default__</uri>
            </script>
          </material>
        </visual>
        <gravity>1</gravity>
        <velocity_decay>
          <linear>0</linear>
          <angular>0</angular>
        </velocity_decay>
        <self_collide>0</self_collide>
        <kinematic>0</kinematic>
      </link>
      <joint name='wheel_joint_bl' type='revolute'>
        <child>wheel_link_bl</child>
        <parent>caster_link_bl</parent>
        <axis>
          <xyz>0 1 0</xyz>
          <limit>
            <lower>-1e+16</lower>
            <upper>1e+16</upper>
          </limit>
          <dynamics>
            <damping>1</damping>
          </dynamics>
        </axis>
      </joint>
      <link name='caster_link_br'>
        <pose>-4.028 -0.158 -0.034 0 -0 0</pose>
        <inertial>
          <pose>0 0 0 0 -0 0</pose>
          <mass>0.1</mass>
          <inertia>
            <ixx>0.0124118</ixx>
            <ixy>-0.000711734</ixy>
            <ixz>0.00050273</ixz>
            <iyy>0.0152182</iyy>
            <iyz>-4.27347e-06</iyz>
            <izz>0.011764</izz>
          </inertia>
        </inertial>
        <gravity>1</gravity>
        <velocity_decay>
          <linear>0</linear>
          <angular>0</angular>
        </velocity_decay>
        <self_collide>0</self_collide>
        <kinematic>0</kinematic>
      </link>
      <joint name='caster_joint_br' type='revolute'>
        <child>caster_link_br</child>
        <parent>base_footprint</parent>
        <axis>
          <xyz>0 0 1</xyz>
          <limit>
            <lower>-1e+16</lower>
            <upper>1e+16</upper>
          </limit>
          <dynamics>
            <damping>1</damping>
          </dynamics>
        </axis>
      </joint>
      <link name='wheel_link_br'>
        <pose>-4.028 -0.158 -0.034 0 -0 0</pose>
        <inertial>
          <pose>0 0 0 0 -0 0</pose>
          <mass>0.4</mass>
          <inertia>
            <ixx>0.0124118</ixx>
            <ixy>-0.000711734</ixy>
            <ixz>0.00050273</ixz>
            <iyy>0.0152182</iyy>
            <iyz>-4.27347e-06</iyz>
            <izz>0.011764</izz>
          </inertia>
        </inertial>
        <collision name='wheel_link_br_collision'>
          <pose>0 0 0 1.5708 -0 0</pose>
          <geometry>
            <cylinder>
              <length>0.05</length>
              <radius>0.05</radius>
            </cylinder>
          </geometry>
          <surface>
            <contact>
              <ode>
                <kp>1e+06</kp>
                <kd>100</kd>
              </ode>
            </contact>
            <friction>
              <ode/>
            </friction>
            <bounce/>
          </surface>
          <max_contacts>10</max_contacts>
        </collision>
        <visual name='wheel_link_br_visual'>
          <pose>0 0 0 0 -0 0</pose>
          <geometry>
            <sphere>
              <radius>0.05</radius>
            </sphere>
          </geometry>
          <material>
            <script>
              <name>youbot/Orange</name>
              <uri>__default__</uri>
            </script>
          </material>
        </visual>
        <gravity>1</gravity>
        <velocity_decay>
          <linear>0</linear>
          <angular>0</angular>
        </velocity_decay>
        <self_collide>0</self_collide>
        <kinematic>0</kinematic>
      </link>
      <joint name='wheel_joint_br' type='revolute'>
        <child>wheel_link_br</child>
        <parent>caster_link_br</parent>
        <axis>
          <xyz>0 1 0</xyz>
          <limit>
            <lower>-1e+16</lower>
            <upper>1e+16</upper>
          </limit>
          <dynamics>
            <damping>1</damping>
          </dynamics>
        </axis>
      </joint>
      <link name='caster_link_fl'>
        <pose>-3.572 0.158 -0.034 0 -0 0</pose>
        <inertial>
          <pose>0 0 0 0 -0 0</pose>
          <mass>0.1</mass>
          <inertia>
            <ixx>0.0124118</ixx>
            <ixy>-0.000711734</ixy>
            <ixz>0.00050273</ixz>
            <iyy>0.0152182</iyy>
            <iyz>-4.27347e-06</iyz>
            <izz>0.011764</izz>
          </inertia>
        </inertial>
        <gravity>1</gravity>
        <velocity_decay>
          <linear>0</linear>
          <angular>0</angular>
        </velocity_decay>
        <self_collide>0</self_collide>
        <kinematic>0</kinematic>
      </link>
      <joint name='caster_joint_fl' type='revolute'>
        <child>caster_link_fl</child>
        <parent>base_footprint</parent>
        <axis>
          <xyz>0 0 1</xyz>
          <limit>
            <lower>-1e+16</lower>
            <upper>1e+16</upper>
          </limit>
          <dynamics>
            <damping>1</damping>
          </dynamics>
        </axis>
      </joint>
      <link name='wheel_link_fl'>
        <pose>-3.572 0.158 -0.034 0 -0 0</pose>
        <inertial>
          <pose>0 0 0 0 -0 0</pose>
          <mass>0.4</mass>
          <inertia>
            <ixx>0.0124118</ixx>
            <ixy>-0.000711734</ixy>
            <ixz>0.00050273</ixz>
            <iyy>0.0152182</iyy>
            <iyz>-4.27347e-06</iyz>
            <izz>0.011764</izz>
          </inertia>
        </inertial>
        <collision name='wheel_link_fl_collision'>
          <pose>0 0 0 1.5708 -0 0</pose>
          <geometry>
            <cylinder>
              <length>0.05</length>
              <radius>0.05</radius>
            </cylinder>
          </geometry>
          <surface>
            <contact>
              <ode>
                <kp>1e+06</kp>
                <kd>100</kd>
              </ode>
            </contact>
            <friction>
              <ode/>
            </friction>
            <bounce/>
          </surface>
          <max_contacts>10</max_contacts>
        </collision>
        <visual name='wheel_link_fl_visual'>
          <pose>0 0 0 0 -0 0</pose>
          <geometry>
            <sphere>
              <radius>0.05</radius>
            </sphere>
          </geometry>
          <material>
            <script>
              <name>youbot/Orange</name>
              <uri>__default__</uri>
            </script>
          </material>
        </visual>
        <gravity>1</gravity>
        <velocity_decay>
          <linear>0</linear>
          <angular>0</angular>
        </velocity_decay>
        <self_collide>0</self_collide>
        <kinematic>0</kinematic>
      </link>
      <joint name='wheel_joint_fl' type='revolute'>
        <child>wheel_link_fl</child>
        <parent>caster_link_fl</parent>
        <axis>
          <xyz>0 1 0</xyz>
          <limit>
            <lower>-1e+16</lower>
            <upper>1e+16</upper>
          </limit>
          <dynamics>
            <damping>1</damping>
          </dynamics>
        </axis>
      </joint>
      <link name='caster_link_fr'>
        <pose>-3.572 -0.158 -0.034 0 -0 0</pose>
        <inertial>
          <pose>0 0 0 0 -0 0</pose>
          <mass>0.1</mass>
          <inertia>
            <ixx>0.0124118</ixx>
            <ixy>-0.000711734</ixy>
            <ixz>0.00050273</ixz>
            <iyy>0.0152182</iyy>
            <iyz>-4.27347e-06</iyz>
            <izz>0.011764</izz>
          </inertia>
        </inertial>
        <gravity>1</gravity>
        <velocity_decay>
          <linear>0</linear>
          <angular>0</angular>
        </velocity_decay>
        <self_collide>0</self_collide>
        <kinematic>0</kinematic>
      </link>
      <joint name='caster_joint_fr' type='revolute'>
        <child>caster_link_fr</child>
        <parent>base_footprint</parent>
        <axis>
          <xyz>0 0 1</xyz>
          <limit>
            <lower>-1e+16</lower>
            <upper>1e+16</upper>
          </limit>
          <dynamics>
            <damping>1</damping>
          </dynamics>
        </axis>
      </joint>
      <link name='wheel_link_fr'>
        <pose>-3.572 -0.158 -0.034 0 -0 0</pose>
        <inertial>
          <pose>0 0 0 0 -0 0</pose>
          <mass>0.4</mass>
          <inertia>
            <ixx>0.0124118</ixx>
            <ixy>-0.000711734</ixy>
            <ixz>0.00050273</ixz>
            <iyy>0.0152182</iyy>
            <iyz>-4.27347e-06</iyz>
            <izz>0.011764</izz>
          </inertia>
        </inertial>
        <collision name='wheel_link_fr_collision'>
          <pose>0 0 0 1.5708 -0 0</pose>
          <geometry>
            <cylinder>
              <length>0.05</length>
              <radius>0.05</radius>
            </cylinder>
          </geometry>
          <surface>
            <contact>
              <ode>
                <kp>1e+06</kp>
                <kd>100</kd>
              </ode>
            </contact>
            <friction>
              <ode/>
            </friction>
            <bounce/>
          </surface>
          <max_contacts>10</max_contacts>
        </collision>
        <visual name='wheel_link_fr_visual'>
          <pose>0 0 0 0 -0 0</pose>
          <geometry>
            <sphere>
              <radius>0.05</radius>
            </sphere>
          </geometry>
          <material>
            <script>
              <name>youbot/Orange</name>
              <uri>__default__</uri>
            </script>
          </material>
        </visual>
        <gravity>1</gravity>
        <velocity_decay>
          <linear>0</linear>
          <angular>0</angular>
        </velocity_decay>
        <self_collide>0</self_collide>
        <kinematic>0</kinematic>
      </link>
      <joint name='wheel_joint_fr' type='revolute'>
        <child>wheel_link_fr</child>
        <parent>caster_link_fr</parent>
        <axis>
          <xyz>0 1 0</xyz>
          <limit>
            <lower>-1e+16</lower>
            <upper>1e+16</upper>
          </limit>
          <dynamics>
            <damping>1</damping>
          </dynamics>
        </axis>
      </joint>
      <plugin name='gazebo_ros_controller' filename='libgazebo_ros_control.so'>
        <robotNamespace>/</robotNamespace>
      </plugin>
      <static>0</static>
      <plugin name='base_controller' filename='libgazebo_ros_planar_move.so'>
        <commandTopic>cmd_vel</commandTopic>
        <odometryTopic>odom</odometryTopic>
        <odometryFrame>odom</odometryFrame>
        <odometryRate>100.0</odometryRate>
        <robotBaseFrame>base_footprint</robotBaseFrame>
        <robotNamespace>/</robotNamespace>
      </plugin>
      <pose>0 0 0 0 -0 0</pose>
    </model>
    <model name='coke_can'>
      <link name='link'>
        <inertial>
          <pose>-0.01 -0.012 0.15 0 -0 0</pose>
          <mass>0.39</mass>
          <inertia>
            <ixx>0.00058</ixx>
            <ixy>0</ixy>
            <ixz>0</ixz>
            <iyy>0.00058</iyy>
            <iyz>0</iyz>
            <izz>0.00019</izz>
          </inertia>
        </inertial>
        <collision name='collision'>
          <pose>0 0 -0.46 0 -0 0</pose>
          <geometry>
            <mesh>
              <uri>model://coke_can/meshes/coke_can.dae</uri>
            </mesh>
          </geometry>
          <surface>
            <friction>
              <ode>
                <mu>1</mu>
                <mu2>1</mu2>
              </ode>
            </friction>
            <contact>
              <ode>
                <kp>1e+07</kp>
                <kd>1</kd>
                <min_depth>0.001</min_depth>
                <max_vel>0.1</max_vel>
              </ode>
            </contact>
            <bounce/>
          </surface>
          <max_contacts>10</max_contacts>
        </collision>
        <visual name='visual'>
          <pose>0 0 -0.46 0 -0 0</pose>
          <geometry>
            <mesh>
              <uri>model://coke_can/meshes/coke_can.dae</uri>
            </mesh>
          </geometry>
        </visual>
        <velocity_decay>
          <linear>0</linear>
          <angular>0</angular>
        </velocity_decay>
        <self_collide>0</self_collide>
        <kinematic>0</kinematic>
        <gravity>1</gravity>
      </link>
      <pose>1 0 0 0 -0 0</pose>
      <static>0</static>
    </model>
    <state world_name='default'>
      <sim_time>552 348000000</sim_time>
      <real_time>555 226745606</real_time>
      <wall_time>1518976652 437634811</wall_time>
      <model name='coke_can'>
        <pose>0.999987 -5.6e-05 -0.003988 -0.01578 0.003494 0.000221</pose>
        <link name='link'>
          <pose>0.999987 -5.6e-05 -0.003988 -0.01578 0.003494 0.000221</pose>
          <velocity>0 0 0 0 -0 0</velocity>
          <acceleration>0 0 0 0 -0 0</acceleration>
          <wrench>0 0 0 0 -0 0</wrench>
        </link>
      </model>
      <model name='ground_plane'>
        <pose>0 0 0 0 -0 0</pose>
        <link name='link'>
          <pose>0 0 0 0 -0 0</pose>
          <velocity>0 0 0 0 -0 0</velocity>
          <acceleration>0 0 0 0 -0 0</acceleration>
          <wrench>0 0 0 0 -0 0</wrench>
        </link>
      </model>
      <model name='world'>
        <pose>0 0 0.149996 -3e-06 2e-06 -1e-06</pose>
        <link name='wall_1'>
          <pose>0 0 0.149996 -3e-06 2e-06 -1e-06</pose>
          <velocity>0 0 0 0 -0 0</velocity>
          <acceleration>0 0 0 0 -0 0</acceleration>
          <wrench>0 0 0 0 -0 0</wrench>
        </link>
      </model>
      <model name='youbot'>
        <pose>0.979767 0.169087 0.083861 7e-06 2.6e-05 -0.224289</pose>
        <link name='arm_link_1'>
          <pose>-2.56223 0.977114 0.225954 1.69407e-21 -2.6e-05 2.70671</pose>
          <velocity>0.000128 -5.2e-05 -0.005737 0.000261 0.000641 0.00052</velocity>
          <acceleration>0 0 0 0 -0 0</acceleration>
          <wrench>0 0 0 0 -0 0</wrench>
        </link>
        <link name='arm_link_2'>
          <pose>-2.59216 0.991017 0.244955 2.3e-05 -1.08963 2.70671</pose>
          <velocity>0.00014 -7.4e-05 -0.0057 -0.004434 -0.00889 0.001111</velocity>
          <acceleration>0 0 0 0 -0 0</acceleration>
          <wrench>0 0 0 0 -0 0</wrench>
        </link>
        <link name='arm_link_3'>
          <pose>-2.46755 0.933135 0.31669 0.000354 1.38859 2.70709</pose>
          <velocity>-0.00049 0.000231 -0.004262 0.013359 0.028105 0.001138</velocity>
          <acceleration>0 0 0 0 -0 0</acceleration>
          <wrench>0 0 0 0 -0 0</wrench>
        </link>
        <link name='arm_link_4'>
          <pose>-2.58796 0.989066 0.341157 8.2e-05 -0.3356 2.70673</pose>
          <velocity>0.000148 -0.000232 -9.5e-05 0.000223 -0.000223 0.00122</velocity>
          <acceleration>0 0 0 0 -0 0</acceleration>
          <wrench>0 0 0 0 -0 0</wrench>
        </link>
        <link name='arm_link_5'>
          <pose>-2.54741 0.970237 0.463248 -0.079188 0.326467 -0.677204</pose>
          <velocity>0.000129 -0.000235 -7.6e-05 -0.000124 -9.2e-05 2.9e-05</velocity>
          <acceleration>0 0 0 0 -0 0</acceleration>
          <wrench>0 0 0 0 -0 0</wrench>
        </link>
        <link name='base_footprint'>
          <pose>0.979767 0.169087 0.083861 7e-06 2.6e-05 -0.224289</pose>
          <velocity>2.3e-05 -7.5e-05 -0.008191 0.000278 0.000628 -1.7e-05</velocity>
          <acceleration>0 0 0 0 -0 0</acceleration>
          <wrench>0 0 0 0 -0 0</wrench>
        </link>
        <link name='caster_link_bl'>
          <pose>-2.9122 1.21901 0.049967 7e-06 2.6e-05 -0.220759</pose>
          <velocity>2.8e-05 -1e-05 -0.005579 0.000277 0.000627 -1.7e-05</velocity>
          <acceleration>0 0 0 0 -0 0</acceleration>
          <wrench>0 0 0 0 -0 0</wrench>
        </link>
        <link name='caster_link_br'>
          <pose>-2.98248 0.910927 0.049965 7e-06 2.6e-05 -0.227248</pose>
          <velocity>2.6e-05 -1e-05 -0.005668 0.000278 0.000627 -1.7e-05</velocity>
          <acceleration>0 0 0 0 -0 0</acceleration>
          <wrench>0 0 0 0 -0 0</wrench>
        </link>
        <link name='caster_link_fl'>
          <pose>-2.46762 1.11759 0.049957 7e-06 2.6e-05 -0.219578</pose>
          <velocity>2.7e-05 -1.2e-05 -0.006149 0.00028 0.000628 -1.8e-05</velocity>
          <acceleration>0 0 0 0 -0 0</acceleration>
          <wrench>0 0 0 0 -0 0</wrench>
        </link>
        <link name='caster_link_fr'>
          <pose>-2.5379 0.809506 0.049951 7e-06 2.6e-05 -0.225017</pose>
          <velocity>8e-06 -1e-06 -0.005677 0.000279 0.00063 -1.9e-05</velocity>
          <acceleration>0 0 0 0 -0 0</acceleration>
          <wrench>0 0 0 0 -0 0</wrench>
        </link>
        <link name='gripper_finger_link_l'>
          <pose>-2.52081 0.974475 0.504171 0.079188 -0.326467 2.46439</pose>
          <velocity>0.000186 -0.00015 -8.1e-05 -0.000122 -9.4e-05 2.8e-05</velocity>
          <acceleration>0 0 0 0 -0 0</acceleration>
          <wrench>0 0 0 0 -0 0</wrench>
        </link>
        <link name='gripper_finger_link_r'>
          <pose>-2.53966 0.949771 0.506505 -0.079187 0.326467 -0.677204</pose>
          <velocity>0.000186 -0.00015 -8e-05 -0.000119 -9.8e-05 2.6e-05</velocity>
          <acceleration>0 0 0 0 -0 0</acceleration>
          <wrench>0 0 0 0 -0 0</wrench>
        </link>
        <link name='wheel_link_bl'>
          <pose>-2.9122 1.21901 0.049967 6e-06 0.001493 -0.220759</pose>
          <velocity>3e-05 -1.3e-05 -0.005565 0.000263 0.000593 -1.4e-05</velocity>
          <acceleration>0 0 0 0 -0 0</acceleration>
          <wrench>0 0 0 0 -0 0</wrench>
        </link>
        <link name='wheel_link_br'>
          <pose>-2.98248 0.910927 0.049965 7e-06 -0.017992 -0.227248</pose>
          <velocity>2.9e-05 -1.3e-05 -0.005649 0.000264 0.00059 -1.4e-05</velocity>
          <acceleration>0 0 0 0 -0 0</acceleration>
          <wrench>0 0 0 0 -0 0</wrench>
        </link>
        <link name='wheel_link_fl'>
          <pose>-2.46762 1.11759 0.049956 7e-06 0.044798 -0.219577</pose>
          <velocity>3e-05 -1.4e-05 -0.006106 0.000275 0.000592 -1.4e-05</velocity>
          <acceleration>0 0 0 0 -0 0</acceleration>
          <wrench>0 0 0 0 -0 0</wrench>
        </link>
        <link name='wheel_link_fr'>
          <pose>-2.5379 0.809506 0.049954 7e-06 0.026377 -0.225017</pose>
          <velocity>2.9e-05 -1.4e-05 -0.006162 0.000275 0.000585 -1.5e-05</velocity>
          <acceleration>0 0 0 0 -0 0</acceleration>
          <wrench>0 0 0 0 -0 0</wrench>
        </link>
      </model>
    </state>
    <gui fullscreen='0'>
      <camera name='user_camera'>
        <pose>3.21226 -6.18079 2.06406 0 0.291643 1.98819</pose>
        <view_controller>orbit</view_controller>
      </camera>
    </gui>
  </world>
</sdf>
